Traceback (most recent call last):
  File "/home/olav/.pyenv/versions/exams/lib/python3.12/site-packages/jupyter_cache/executors/utils.py", line 58, in single_nb_execution
    executenb(
  File "/home/olav/.pyenv/versions/exams/lib/python3.12/site-packages/nbclient/client.py", line 1314, in execute
    return NotebookClient(nb=nb, resources=resources, km=km, **kwargs).execute()
           ^^^^^^^^^^^^^^^^^^^^^^^^^^^^^^^^^^^^^^^^^^^^^^^^^^^^^^^^^^^^^^^^^^^^^
  File "/home/olav/.pyenv/versions/exams/lib/python3.12/site-packages/jupyter_core/utils/__init__.py", line 165, in wrapped
    return loop.run_until_complete(inner)
           ^^^^^^^^^^^^^^^^^^^^^^^^^^^^^^
  File "/home/olav/.pyenv/versions/3.12.0/lib/python3.12/asyncio/base_events.py", line 664, in run_until_complete
    return future.result()
           ^^^^^^^^^^^^^^^
  File "/home/olav/.pyenv/versions/exams/lib/python3.12/site-packages/nbclient/client.py", line 709, in async_execute
    await self.async_execute_cell(
  File "/home/olav/.pyenv/versions/exams/lib/python3.12/site-packages/nbclient/client.py", line 1062, in async_execute_cell
    await self._check_raise_for_error(cell, cell_index, exec_reply)
  File "/home/olav/.pyenv/versions/exams/lib/python3.12/site-packages/nbclient/client.py", line 918, in _check_raise_for_error
    raise CellExecutionError.from_cell_and_msg(cell, exec_reply_content)
nbclient.exceptions.CellExecutionError: An error occurred while executing the following cell:
------------------
assert GBP(1, -19, 0) == GBP(0, 1, 0) # This is fine


import pytest
with pytest.raises(NegativePounds):
    GBP(1, -21, 0) # Not fine
------------------


[0;31m---------------------------------------------------------------------------[0m
[0;31mModuleNotFoundError[0m                       Traceback (most recent call last)
Cell [0;32mIn[17], line 4[0m
[1;32m      1[0m [38;5;28;01massert[39;00m GBP([38;5;241m1[39m, [38;5;241m-[39m[38;5;241m19[39m, [38;5;241m0[39m) [38;5;241m==[39m GBP([38;5;241m0[39m, [38;5;241m1[39m, [38;5;241m0[39m) [38;5;66;03m# This is fine[39;00m
[0;32m----> 4[0m [38;5;28;01mimport[39;00m [38;5;21;01mpytest[39;00m
[1;32m      5[0m [38;5;28;01mwith[39;00m pytest[38;5;241m.[39mraises(NegativePounds):
[1;32m      6[0m     GBP([38;5;241m1[39m, [38;5;241m-[39m[38;5;241m21[39m, [38;5;241m0[39m) [38;5;66;03m# Not fine[39;00m

[0;31mModuleNotFoundError[0m: No module named 'pytest'

